Workbook
Name equipos: OFFSET([1]Data!$F$4,0,0,COUNTA([1]Data!$F$4:$F$52),1)
Name equipos: OFFSET([1]Data!$F$4,0,0,COUNTA([1]Data!$F$4:$F$52),1)
Name equipos: OFFSET([1]Data!$F$4,0,0,COUNTA([1]Data!$F$4:$F$52),1)
Name equipos: OFFSET(Data!$F$4,0,0,COUNTA(Data!$F$4:$F$53),1)
Name nombres: OFFSET([1]Data!$B$4,0,0,COUNTA([1]Data!$B$4:$B$52),1)
Name nombres: OFFSET([1]Data!$B$4,0,0,COUNTA([1]Data!$B$4:$B$52),1)
Name nombres: OFFSET([1]Data!$B$4,0,0,COUNTA([1]Data!$B$4:$B$52),1)
Name nombres: OFFSET(Data!$B$4,0,0,COUNTA(Data!$B$4:$B$53),1)
Name obra_actividad: OFFSET([1]Data!$M$4,0,0,COUNTA([1]Data!$M$4:$M$152),1)
Name obra_actividad: OFFSET([1]Data!$M$4,0,0,COUNTA([1]Data!$M$4:$M$152),1)
Name obra_actividad: OFFSET([1]Data!$M$4,0,0,COUNTA([1]Data!$M$4:$M$152),1)
Name obra_actividad: OFFSET(Data!$M$4,0,0,COUNTA(Data!$M$4:$M$153),1)
Name origen_destino: OFFSET([1]Data!$J$4,0,0,COUNTA([1]Data!$J$4:$J$52),1)
Name origen_destino: OFFSET([1]Data!$J$4,0,0,COUNTA([1]Data!$J$4:$J$52),1)
Name origen_destino: OFFSET([1]Data!$J$4,0,0,COUNTA([1]Data!$J$4:$J$52),1)
Name origen_destino: OFFSET(Data!$J$4,0,0,COUNTA(Data!$J$4:$J$53),1)
Name servicio_fin: OFFSET([1]Data!$G$4,0,0,COUNTA([1]Data!$G$4:$G$52),1)
Name servicio_fin: OFFSET([1]Data!$G$4,0,0,COUNTA([1]Data!$G$4:$G$52),1)
Name servicio_fin: OFFSET([1]Data!$G$4,0,0,COUNTA([1]Data!$G$4:$G$52),1)
Name servicio_fin: OFFSET(Data!$G$4,0,0,COUNTA(Data!$G$4:$G$53),1)

Sheet 8.Feb
B2: PARTE DIARIO DE SERVICIOS
B3: DATOS GENERALES
B4: Empresa colaboradora: | J4: Zona: | K4: Fecha:
B5: BUREAU VERITAS DEL PERÚ | J5: COSTA | K5: 45696
B6: PERSONAL
B7: N | C7: NOMBRE | F7: ORIGEN | G7: DESTINO | H7: SERVICIO | J7: ACTIVIDAD | K7: CUENTA | L7: ORDEN
B8: 1 | C8: BENDEZÚ RODRIGUEZ, FRANK | F8: PISCO | G8: PISCO | H8: =+IFERROR(VLOOKUP(C8,Data!B:C,2,0),"") -> COST CONTROL SEMI SENIOR | J8: SOPORTE CONTROL DE COSTOS | K8: =+IFERROR(VLOOKUP(J8,Data!M:O,2,0),"") -> A111004 | L8: =+IFERROR(VLOOKUP(J8,Data!M:O,3,0),"") -> TGGT-2509
B9: EQUIPOS
B10: N | C10: EQUIPO | D10: KM INICIO | E10: KM FIN | F10: ORIGEN | G10: DESTINO | H10: SERVICIO | J10: ACTIVIDAD | K10: CUENTA | L10: ORDEN | N10: EQUIPO | O10: RECORRIDO | P10: A CERTIFICAR
N11: =MID(C11,11,7) | O11: =E11-D11 -> 0 | P11: =+O11 -> 0
B13: COMENTARIOS | N13: =MID(C13,11,7)
B14: ' 01 Cost Control - Frank Bendezú Cost control, realiza: 1.- Se actualizó el estatus de los entregables (pdp y rd´s) del mes de enero y febrero 2.- Se actualizó el one drive de tgp 3.- Se revisó el cronograma de topografia del mes de febrero
B16: REPRESENTANTE BUREAU VERITAS | I16: REPRESENTANTE DE TGP
B17: Firma: | I17: Firma:
B19: Nombre: Roselma Velásquez Florián | I19: Nombre:

Sheet 9.Feb
B2: PARTE DIARIO DE SERVICIOS
B3: DATOS GENERALES
B4: Empresa colaboradora: | J4: Zona: | K4: Fecha:
B5: BUREAU VERITAS DEL PERÚ | J5: COSTA | K5: 45697
B6: PERSONAL
B7: N | C7: NOMBRE | F7: ORIGEN | G7: DESTINO | H7: SERVICIO | J7: ACTIVIDAD | K7: CUENTA | L7: ORDEN
B8: 1 | C8: BENDEZÚ RODRIGUEZ, FRANK | F8: PISCO | G8: PISCO | H8: =+IFERROR(VLOOKUP(C8,Data!B:C,2,0),"") -> COST CONTROL SEMI SENIOR | J8: SOPORTE CONTROL DE COSTOS | K8: =+IFERROR(VLOOKUP(J8,Data!M:O,2,0),"") -> A111004 | L8: =+IFERROR(VLOOKUP(J8,Data!M:O,3,0),"") -> TGGT-2509
B9: EQUIPOS
B10: N | C10: EQUIPO | D10: KM INICIO | E10: KM FIN | F10: ORIGEN | G10: DESTINO | H10: SERVICIO | J10: ACTIVIDAD | K10: CUENTA | L10: ORDEN | N10: EQUIPO | O10: RECORRIDO | P10: A CERTIFICAR
N11: =MID(C11,11,7) | O11: =E11-D11 -> 0 | P11: =+O11 -> 0
B13: COMENTARIOS | N13: =MID(C13,11,7)
B14: ' 01 Cost Control - Frank Bendezú Cost control, realiza: 1.- Se actualizó el estatus de los entregables (pdp y rd´s) del mes de enero y febrero 2.- Se actualizó el one drive de tgp 3.- Se revisó el cronograma de topografia del mes de febrero
B16: REPRESENTANTE BUREAU VERITAS | I16: REPRESENTANTE DE TGP
B17: Firma: | I17: Firma:
B19: Nombre: Roselma Velásquez Florián | I19: Nombre:

Sheet 01 Marzo
B2: PARTE DIARIO DE SERVICIOS
B3: DATOS GENERALES
B4: Empresa colaboradora: | J4: Zona: | K4: Fecha:
B5: BUREAU VERITAS DEL PERÚ
B6: PERSONAL
B7: N | C7: NOMBRE | F7: ORIGEN | G7: DESTINO | H7: SERVICIO | J7: ACTIVIDAD | K7: CUENTA | L7: ORDEN | P7: . | R7: .
B8: 1
B9: EQUIPOS
B10: N | C10: EQUIPO | D10: KM INICIO | E10: KM FIN | F10: ORIGEN | G10: DESTINO | H10: SERVICIO | J10: ACTIVIDAD | K10: CUENTA | L10: ORDEN | N10: EQUIPO | O10: RECORRIDO | P10: A CERTIFICAR | T10: .
B11: 1
B12: 1 | S12: .
B13: COMENTARIOS
R14: .
B16: REPRESENTANTE BUREAU VERITAS | I16: REPRESENTANTE DE TGP
B17: Firma: | I17: Firma:
B19: Nombre: Yuri Arangoitia. R | I19: Nombre:

Sheet Data
A3: n | B3: APELLIDOS Y NOMBRES | C3: SERVICIO (PERSONAL) | E3: n | F3: EQUIPOS | G3: SERVICIO (EQUIPOS) | I3: n | J3: ORIGEN/DESTINO | L3: n | M3: OBRA / ACTIVIDAD | N3: CUENTA | O3: ORDEN
A4: 1 | B4: GALLO ALVAREZ, JORDAN ERWIN | C4: SUPERVISOR DE GEOTECNIA SENIOR | E4: 1 | F4: CAMIONETA BUJ-832 | G4: ALQUILER DE CAMIONETA SIN CONDUCTOR | I4: 1 | J4: BOSC | L4: 1 | M4: SOPORTE A INGENIERIA | N4: A111004 | O4: TGGT-2509
A5: =+A4+1 -> 2 | B5: HERRADA BARRETO, YONTAN ROY | C5: SUPERVISOR DE GEOTECNIA SENIOR | E5: =+E4+1 -> 2 | F5: SATELITAL - IMEI 353032044599898 / 870776413854 | G5: ALQUILER TELEFONO SATELITAL | I5: =+I4+1 -> 2 | J5: PISCO | L5: =+L4+1 -> 2 | M5: SOPORTE CONTROL DE COSTOS | N5: A111004 | O5: TGGT-2509
A6: =+A5+1 -> 3 | B6: GUERRERO MALCA, MARIANELLA | C6: SUPERVISOR DE GEOTECNIA SEMI SENIOR | E6: 3 | F6: CAMIONETA BUO-858 | G6: ALQUILER DE CAMIONETA SIN CONDUCTOR | I6: =+I5+1 -> 3 | J6: CAÑETE | L6: =+L5+1 -> 3 | M6: TAI KP 509 - QDA AUQUIX | N6: 6343015 | O6: TGEO-2513
A7: =+A6+1 -> 4 | B7: CHINCHAY CHOMBA, HUGO | C7: SUPERVISOR DE GEOTECNIA SEMI SENIOR | E7: 4 | F7: CAMIONETA BUK-723 | G7: ALQUILER DE CAMIONETA SIN CONDUCTOR | I7: =+I6+1 -> 4 | J7: CHINCHA | L7: =+L6+1 -> 4 | M7: TAI MV PRS2 | N7: 6343002 | O7: TG3CDV1
A8: =+A7+1 -> 5 | B8: GINES BENAVIDES, JORGE EDUARDO | C8: CONDUCTOR | E8: 5 | F8: CAMIONETA ATF-929 | G8: ALQUILER DE CAMIONETA SIN CONDUCTOR | I8: =+I7+1 -> 5 | J8: HUMAY | L8: =+L7+1 -> 5 | M8: TAI KP 726+140 | N8: 6343015 | O8: TGEO-2513
A9: =+A8+1 -> 6 | B9: LAZO QUISPE, LUIS | C9: CONDUCTOR | E9: 6 | F9: CAMIONETA BVJ-872 | G9: ALQUILER DE CAMIONETA SIN CONDUCTOR | I9: =+I8+1 -> 6 | J9: MALA | L9: =+L8+1 -> 6 | M9: VIGILANCIA | N9: 6343016 | O9: TG3CDV1
A10: =+A9+1 -> 7 | B10: ZANABRIA VILLALBA, FREDY | C10: CONDUCTOR | E10: 7 | F10: CAMIONETA AZJ- 736 | G10: ALQUILER DE CAMIONETA SIN CONDUCTOR | I10: =+I9+1 -> 7 | J10: LIMA | L10: =+L9+1 -> 7 | M10: MG KP701+616 -KP 714+155 | N10: 6343015 | O10: TGEO-2548
A11: =+A10+1 -> 8 | B11: GARCIA ROBLES, OSCAR | C11: CONDUCTOR | E11: 8 | F11: CAMIONETA BVD-878 | G11: ALQUILER DE CAMIONETA SIN CONDUCTOR | I11: =+I10+1 -> 8 | J11: PRS2 | L11: =+L10+1 -> 8 | M11: MG - Kp 683+035 - Kp699+555 | N11: 6343015 | O11: TGEO-2547
A12: =+A11+1 -> 9 | B12: CABRERA MANRIQUE, MARTIN | C12: CONDUCTOR | E12: 9 | F12: CAMIONETA ATF-932 | G12: ALQUILER DE CAMIONETA SIN CONDUCTOR | I12: =+I11+1 -> 9 | J12: Kp622 - Kp612+400 | L12: =+L11+1 -> 9 | M12: MG - Kp 670 - Kp683 | N12: 6343015 | O12: TGEO-2554
A13: =+A12+1 -> 10 | B13: CUETO FLORES, CIRILO | C13: CONDUCTOR | E13: 10 | F13: CAMIONETA BVD-807 | G13: ALQUILER DE CAMIONETA SIN CONDUCTOR | I13: =+I12+1 -> 10 | J13: LURIN | L13: =+L12+1 -> 10 | M13: OG_KP 726 | N13: 6343020 | O13: TGGT-2512
A14: =+A13+1 -> 11 | B14: ZANABRIA VILLALBA, DIEGO | C14: CONDUCTOR | E14: 11 | F14: CAMIONETA CCQ- 709 | G14: ALQUILER DE CAMIONETA SIN CONDUCTOR | I14: =+I13+1 -> 11 | J14: MALANCHE | L14: =+L13+1 -> 11 | M14: MG-KP 519 - 554 | N14: 6343015 | O14: TGEO-2546
A15: =+A14+1 -> 12 | B15: BAQUERIZO CONDORI, CHISTIAN | C15: SUPERVISOR DE GEOTECNIA SENIOR | E15: 12 | F15: CAMIONETA BVD - 807 | I15: =+I14+1 -> 12 | J15: 3ER CRUCE | L15: =+L14+1 -> 12 | M15: OG_KP 572 | N15: 6343020 | O15: TGGT-2517
A16: =+A15+1 -> 13 | B16: TRIGOSO PINTO, CESAR FRANCISCO | C16: CONDUCTOR | E16: 13 | F16: CAMIONETA W7D - 707 | G16: ALQUILER DE CAMIONETA SIN CONDUCTOR | I16: 13 | J16: HUANCANO | L16: =+L15+1 -> 13 | M16: MG Kp554 a Kp581 | N16: 6343015 | O16: TGGT-2552
A17: =+A16+1 -> 14 | B17: BENDEZÚ RODRIGUEZ, FRANK | C17: COST CONTROL SEMI SENIOR | E17: 14 | F17: CAMIOENTA BUJ - 832 | G17: ALQUILER DE CAMIONETA SIN CONDUCTOR | I17: 14 | J17: KP 455+000 | L17: =+L16+1 -> 14 | M17: MG KP 610+118 al KP 621+616 | N17: 6343015 | O17: TGGT-2553
A18: =+A17+1 -> 15 | B18: MARQUEZ CAPANNI, JOSÉ MANUEL | C18: SUPERVISOR DE GEOTECNIA SENIOR | E18: 15 | F18: CAMIOENTA BVD - 793 | G18: ALQUILER DE CAMIONETA SIN CONDUCTOR | I18: 15 | J18: KP 456+000 | L18: =+L17+1 -> 15 | M18: MANTENIMIENTO VIAL - ACCESO PRS2 | N18: 6343002 | O18: TG1CDV1
A19: =+A18+1 -> 16 | B19: RAMIREZ SALDAÑA, CRISTIAN | C19: SUPERVISOR DE GEOTECNIA SEMI SENIOR | E19: 16 | I19: 16 | J19: KP 459+000 | L19: =+L18+1 -> 16 | M19: MG Kp 480+000- Kp 493+620 | N19: 6343015
A20: =+A19+1 -> 17 | B20: DE LA CRUZ JASCINTO, CARLOS AUGUSTO | C20: SUPERVISOR DE GEOTECNIA SEMI SENIOR | E20: 17 | I20: 17 | J20: HUAYTARÁ | L20: =+L19+1 -> 17 | N20: 6343015 | O20: TGEO-2550
A21: =+A20+1 -> 18 | B21: ALVARADO ESPINOZA, ALEXANDER | C21: SUPERVISOR DE GEOTECNIA SENIOR | E21: 18 | I21: 18 | J21: KP 461+500 | L21: =+L20+1 -> 18 | M21: MANTENIMIENTO VIAL - ACCESO RIO CAÑETE | N21: 6343002 | O21: TG1CDV1
A22: =+A21+1 -> 19 | B22: SANCHEZ QUIHUI, JOSE ABEL | C22: SUPERVISOR DE GEOTECNIA SENIOR | E22: 19 | I22: 19 | J22: KP 550+000 | L22: =+L21+1 -> 19 | M22: MG Kp714 aKp730. | N22: 6343015
A23: =+A22+1 -> 20 | B23: NAPA TASAYCO, DAVID | C23: CONDUCTOR | E23: 20 | I23: 20 | J23: TERMINAL | L23: =+L22+1 -> 20
A24: =+A23+1 -> 21 | B24: ARANGOITIA RENDÓN, NIKOLAY | C24: SUPERVISOR GEOTECNISTA SENIOR | E24: 21 | I24: 21 | J24: KP 541+000 | L24: =+L23+1 -> 21
A25: =+A24+1 -> 22 | B25: COLQUE QUISPE, LUIS MIGUEL | C25: SUPERVISOR GEOTECNISTA SEMI SENIOR | E25: 22 | I25: 22 | J25: KP 542+160 | L25: =+L24+1 -> 22
A26: =+A25+1 -> 23 | B26: AMARU HUAMANI, JHONY | C26: CONDUCTOR | E26: 23 | I26: 23 | J26: KP 543+000 | L26: =+L25+1 -> 23
A27: =+A26+1 -> 24 | B27: VELASQUEZ FLORIAN, ROSELMA | C27: SUPERVISOR GEOTECNISTA SENIOR | E27: 24 | I27: 24 | J27: KP 544+000 | L27: =+L26+1 -> 24
A28: =+A27+1 -> 25 | E28: 25 | J28: KP 545+000
A29: =+A28+1 -> 26 | E29: 26 | I29: 25 | J29: Kp540 a Kp558 | L29: =+L27+1 -> 25
A30: =+A29+1 -> 27 | E30: 27 | I30: 26 | J30: Kp673 a Kp720 | L30: =+L29+1 -> 26
A31: =+A30+1 -> 28 | E31: 28 | I31: 27 | J31: Kp702 a Kp726 | L31: =+L30+1 -> 27
A32: =+A31+1 -> 29 | E32: 29 | I32: 28 | J32: Kp487 a Kp545 | L32: =+L31+1 -> 28
A33: =+A32+1 -> 30 | E33: 30 | I33: 29 | J33: Kp520 a Kp521 | L33: =+L32+1 -> 29
A34: =+A33+1 -> 31 | E34: 31 | I34: 30 | J34: Kp523 a Kp526 | L34: =+L33+1 -> 30
A35: =+A34+1 -> 32 | E35: 32 | I35: 31 | J35: Kp525 - Kp534 | L35: =+L34+1 -> 31
A36: =+A35+1 -> 33 | E36: 33 | I36: 32 | J36: KP701 a Kp714 | L36: =+L35+1 -> 32
A37: =+A36+1 -> 34 | E37: 34 | I37: 33 | J37: HUAMANGA | L37: =+L36+1 -> 33
A38: =+A37+1 -> 35 | E38: 35 | I38: 34 | J38: Kp 683+035 | L38: =+L37+1 -> 34
A39: =+A38+1 -> 36 | E39: 35 | I39: 35 | J39: KP 488 | L39: =+L38+1 -> 35
A40: =+A39+1 -> 37 | E40: 35 | I40: 36 | J40: Acceso PRS2 | L40: =+L39+1 -> 36
A41: =+A40+1 -> 38 | I41: 37 | J41: Huamanga | L41: =+L40+1 -> 37
I42: 38 | J42: KP490 | L42: =+L41+1 -> 38
...
